Workbook

Sheet ReadMe
A1: GBF Headline Indicator 3.1 – National Calculation & Reporting Tool
A2: Coverage of protected areas and other effective area-based conservation measures (OECMs) – built on the official metadata (gbf-indicators.org/metadata/headline/3-1, updated 1 Sept 2024)
A4: PURPOSE
A5: What this tool does | B5: Computes Headline Indicator 3.1 for Target 3 of the Kunming-Montreal Global Biodiversity Framework (KMGBF) at national level, plus the five disaggregations listed in the metadata: (1) PAs vs OECMs, (2) realm/biome/ecosystem, (3) Key Biodiversity Areas, (4) management effectiveness, (5) governance type. It also produces a time series, quality-control checks and a reporting dashboard.
A6: What this tool does NOT do | B6: Excel cannot perform spatial operations. The metadata's steps 1–6 (filter, buffer points, merge, flatten/dissolve, erase PA from OECMs, intersect with base map, project to Mollweide) must be done in a GIS (QGIS, ArcGIS, R 'wdpar' package, Python geopandas). The tool takes the resulting areas and performs step 7 (coverage calculation), the disaggregations, the time series and the quality checks. If no GIS capacity exists, the tool falls back to reported/GIS areas per site and flags the result as an upper bound (overlaps may be double-counted).
A7: Relationship with Protected Planet | B7: UNEP-WCMC/IUCN publish monthly national statistics on Protected Planet computed with the same method. This tool lets a country (a) reproduce and reconcile those figures, (b) include national data not yet submitted to the WDPA/WD-OECM, (c) compute the disaggregations that are published only biennially or not at all for its own national ecosystem maps, and (d) document every step for the national report.
A8: SHEET GUIDE
A9: 1. Setup | B9: Country, reporting year, realm areas (base-map denominators), method-compliance declarations, thresholds and optional GIS totals.
A10: 2. PA_OECM_Register | B10: One row per protected area / OECM using WDPA/WD-OECM attribute names. Applies the metadata inclusion filters automatically and flags data-quality issues.
A11: 3. Headline_3.1 | B11: Headline indicator: % terrestrial & inland water and % marine & coastal area covered, split PA vs OECM, distance to the 30% target, inland waters.
A12: 4. Ecosystems | B12: Disaggregation by IUCN Global Ecosystem Typology biome, by Ecosystem Functional Group/ecoregion/national ecosystem type, and inland waters (rivers, lakes & wetlands).
A13: 5. KBA_Coverage | B13: Mean % of each KBA covered by PAs and/or OECMs (aligned with SDG 14.5.1, 15.1.2, 15.4.1).
A14: 6. Governance | B14: Coverage by WDPA governance type and the four IUCN governance types (proxy for 'equitably governed'); supplementary IUCN management categories.
A15: 7. Mgmt_Effectiveness | B15: Coverage by management-effectiveness class (PROVISIONAL – the official methodology is still under development).
A16: 8. Time_Series | B16: Cumulative coverage by year from STATUS_YR, with the metadata's treatment of missing designation years.
A17: 9. QC_Checks | B17: Automated method-compliance and data-quality checks. Resolve every WARN before reporting.
A18: 10. Dashboard | B18: Summary figures and charts for the national report.
A19: 11. Metadata / References | B19: Summary of the official metadata (definitions, method, limitations) and the scientific references.
A20: WORKFLOW
A21: Step 1 – Data | B21: Download the national WDPA and WD-OECM (protectedplanet.net) and add any nationally recognised sites not yet reported. Download KBA polygons (keybiodiversityareas.org) and national ecosystem maps (cross-walked to the Global Ecosystem Typology).
A22: Step 2 – Filter | B22: Remove sites with STATUS 'Proposed' or 'Not Reported', points without REP_AREA, and UNESCO-MAB Biosphere Reserves (the register does this automatically; do the same in GIS).
A23: Step 3 – Buffer points | B23: Buffer point sites with a circle of area = REP_AREA (radius = √(REP_AREA/π), computed in the register column 'Buffer radius').
A24: Step 4 – Flatten & erase | B24: Merge polygons + buffered points; dissolve PAs into one flat layer. For OECMs: erase all areas overlapping PAs, then dissolve. To keep the time series exact, attribute each overlapping area to the EARLIEST-designated site (PAs before OECMs). Then TRANSFER site-level attributes (PAME, governance) from overlapping records that describe the same physical site to the record holding the area – otherwise the effectiveness and governance disaggregations are understated.
A25: Step 5 – Intersect & project | B25: Intersect with the national base map (land + territorial sea/EEZ), project to Mollweide equal-area (ESRI:54009), compute km² for land and sea parts.
A26: Step 6 – Enter | B26: Enter per-site net areas in the register (columns R–S) or the national flattened totals in Setup (override). Enter KBA and ecosystem overlap areas.
A27: Step 7 – Check & report | B27: Review QC_Checks, then report from Headline_3.1 and Dashboard. Record dataset versions in Setup.
A28: COLOUR LEGEND
A29: Yellow cell, blue text | B29: INPUT – enter or paste data here.
A30: Grey cell, black text | B30: CALCULATION – do not overwrite (formulas).
A31: Blue cell, bold | B31: KEY RESULT.
A32: Orange rows | B32: EXAMPLE data from a FICTIONAL country, showing the expected format. Delete/overwrite before use.
A33: Units | B33: All areas in km² (Mollweide equal-area). River length in km. Percentages stored as fractions (0.30 = 30%).

Sheet Setup
A1: 1. Setup – country parameters, denominators and method declarations
A2: Fill every yellow cell. Areas must come from the SAME base map and projection used for the PA/OECM areas.
A3: Parameter | B3: Value | C3: Unit | D3: Notes / source (metadata 3.1)
A4: Country / jurisdiction | B4: Algeria | C4: text
A5: ISO3 code | B5: DZA | C5: text | D5: ISO 3166-1 alpha-3
A6: Reporting year | B6: 2026 | C6: year | D6: Year of the national report / data cut-off
A7: WDPA / WD-OECM release used | B7: WDPA/WD-OECM October 2026 (Protected Planet; UNEP-WCMC map service) | C7: text | D7: Monthly release from protectedplanet.net; record month & year
A8: KBA dataset version | B8: World Database of KBAs, September 2026 release (KBAsGlobal_2026_September, 65 Algeria polygons) | C8: text | D8: World Database of KBAs (BirdLife International on behalf of the KBA Partnership)
A9: Base map used | B9: geoBoundaries ADM0, inland holes filled (land) + Marine Regions EEZ v12 with coastal gaps, minus land (sea); Mollweide ESRI:54009 | C9: text | D9: Metadata: EEZ (VLIZ), World Vector Shoreline 3rd ed., GADM. National official boundaries are acceptable if documented
A10: Terrestrial area (land incl. inland waters) | B10: 2318644.1 | C10: km² | D10: Denominator, terrestrial realm. Mollweide equal-area. (Antarctica excluded globally)
A11: Marine & coastal area (territorial sea + EEZ) | B11: 131439.54 | C11: km² | D11: Denominator, marine realm. Areas beyond national jurisdiction are excluded at national level
A12: Target coverage | B12: 0.3 | C12: fraction | D12: KMGBF Target 3: at least 30% of terrestrial & inland water and of marine & coastal areas
A13: Target year | B13: 2030 | C13: year
A14: PA layer flattened (overlaps dissolved) in GIS? | B14: Y | C14: Y/N | D14: Method step 4: flatten to avoid double counting
A15: OECM layer: PA overlap erased and flattened? | B15: Y | C15: Y/N | D15: OECM method step 4: erase areas where OECMs overlap PAs
A16: Areas computed in Mollweide equal-area projection? | B16: Y | C16: Y/N | D16: Method step 6
A17: Overlaps attributed to earliest-designated site? | B17: Y | C17: Y/N | D17: Needed for an exact time series from per-site net areas (tool recommendation, not in metadata)
A18: OPTIONAL GIS total – PA terrestrial (flattened) | C18: km² | D18: If entered, overrides the register sum in the headline (reconciliation shown in QC)
A19: OPTIONAL GIS total – OECM terrestrial (PA-erased, flattened) | C19: km² | D19: As above
A20: OPTIONAL GIS total – PA marine (flattened) | C20: km² | D20: As above
A21: OPTIONAL GIS total – OECM marine (PA-erased, flattened) | C21: km² | D21: As above
A22: KBA marine classification threshold | B22: 0.05 | C22: fraction | D22: Metadata: a KBA with ≥5% overlap with the ocean is classified as marine
A23: KBA 'complete coverage' threshold | B23: 0.98 | C23: fraction | D23: Tolerance for digitisation error; 98% used by Butchart et al. (2012). National choice – document it
A24: PAME 'High' class – minimum normalised score | B24: 67 | C24: score 0–100 | D24: PROVISIONAL national choice; official effectiveness methodology still under development (UNEP-WCMC, IUCN & JNCC 2023)
A25: PAME 'Moderate' class – minimum normalised score | B25: 33 | C25: score 0–100 | D25: PROVISIONAL national choice; scores below are 'Low'
A26: PAME validity window | B26: 5 | C26: years | D26: Assessments older than this are classed 'Assessment outdated'. National choice
A27: Time-series start year | B27: 1940 | C27: year | D27: Global series starts 1819; choose the year of the first national site or earlier
A29: Worked example: real WDPA/WD-OECM October 2026 records for Algeria (71 PA polygons, 2 PA points, 5 OECMs). Net areas from 03_analysis/scripts/01_gis_flatten.py: points buffered, clipped to land / sea, PAs flattened, OECMs PA-erased and flattened, overlaps attributed to the earliest-designated site.

Sheet PA_OECM_Register
A1: 2. PA & OECM register – one row per site (WDPA / WD-OECM attribute names)
A2: Columns A–Y = inputs. Columns Z–AL = automatic calculations. Net areas (R–S) come from the flattened GIS layers (metadata steps 1–6); if left blank, gross areas are used and flagged.
A3: INPUTS (A–Y) | Z3: CALCULATIONS (Z–AL) – do not edit
A4: WDPAID / national ID | B4: NAME | C4: DESIG_ENG (designation) | D4: DESIG_TYPE | E4: Site type (PA / OECM) [WDPA PA_DEF 1/0] | F4: IUCN_CAT | G4: GOV_TYPE | H4: STATUS | I4: STATUS_YR (0/blank = unknown) | J4: MARINE 0=terr., 1=coastal, 2=marine | K4: Geometry (Polygon / Point) | L4: REP_AREA (km²) | M4: REP_M_AREA (km²) | N4: GIS_AREA (km², Mollweide) | O4: GIS_M_AREA (km², Mollweide) | P4: UNESCO-MAB Biosphere Reserve? (Y/N) | Q4: MAB exception: count anyway? (Y/N) | R4: NET terrestrial area after flattening / PA-erase (km²) | S4: NET marine area after flattening / PA-erase (km²) | T4: PAME assessed? (Y/N) | U4: PAME tool | V4: PAME year | W4: PAME score (normalised 0–100) | X4: Effectiveness class – manual override (optional) | Y4: Notes / source | Z4: INCLUDED in indicator (1/0) | AA4: Exclusion reason | AB4: Gross total area used (km²) | AC4: Gross marine area (km²) | AD4: Gross terrestrial area (km²) | AE4: Net area supplied? (1/0) | AF4: TERRESTRIAL area counted (km²) | AG4: MARINE area counted (km²) | AH4: Designation year known (0 = missing) | AI4: Point buffer radius (km) = √(REP_AREA/π) | AJ4: IUCN governance type (A–D) | AK4: Effectiveness class | AL4: QC flags
A5: 4999 | B5: Tassili n'Ajjer | C5: World Heritage Site (natural or mixed) | D5: International | E5: PA | F5: Not Applicable | G5: Not Reported | H5: Inscribed | I5: 1982 | J5: 0 | K5: Polygon | L5: 72000 | M5: 0 | N5: 75389.987 | O5: 0 | P5: N | R5: 75619.418 | S5: 0 | T5: Y | U5: Other | V5: 2025 | Y5: GD-PAME: IUCN World Heritage Outlook 2025; IUCN World Heritage Outlook 2020; IUCN World Heritage Outlook 2017; World Heritage Outlook Report 2014; Biosphere Reserve Effectiveness of Management Index (BREMi) 2013 (from record 20389); Management Effectiveness Tracking Tool (METT) 2010; Birdlife Important Bird and Biodiversity Area Monitoring (Birdlife IBA) 2001 | Z5: =IF(AND($A5="",$B5=""),"",IF(OR($E5="",$H5="",$H5="Proposed",$H5="Not Reported"),0,IF(AND($P5="Y",$Q5<>"Y"),0,IF(AND($K5="Point",N($L5)<=0),0,IF(AND(N($L5)<=0,N($N5)<=0,N($R5)+N($S5)<=0),0,1))))) | AA5: =IF(AND($A5="",$B5=""),"",IF($E5="","Site type missing",IF($H5="","STATUS missing",IF($H5="Proposed","STATUS = Proposed",IF($H5="Not Reported","STATUS = Not Reported",IF(AND($P5="Y",$Q5<>"Y"),"UNESCO-MAB Biosphere Reserve",IF(AND($K5="Point",N($L5)<=0),"Point without REP_AREA",IF(AND(N($L5)<=0,N($N5)<=0,N($R5)+N($S5)<=0),"No area information","")))))))) | AB5: =IF(AND($A5="",$B5=""),"",IF($K5="Point",N($L5),IF(N($N5)>0,N($N5),N($L5)))) | AC5: =IF(AND($A5="",$B5=""),"",MIN(AB5,IF(N($J5)=0,0,IF(N($J5)=2,AB5,IF(AND($K5<>"Point",N($O5)>0),N($O5),N($M5)))))) | AD5: =IF(AND($A5="",$B5=""),"",MAX(0,AB5-AC5)) | AE5: =IF(AND($A5="",$B5=""),"",IF(OR($R5<>"",$S5<>""),1,0)) | AF5: =IF(AND($A5="",$B5=""),"",IF(Z5=1,IF(AE5=1,N($R5),AD5),0)) | AG5: =IF(AND($A5="",$B5=""),"",IF(Z5=1,IF(AE5=1,N($S5),AC5),0)) | AH5: =IF(AND($A5="",$B5=""),"",IF(AND(ISNUMBER($I5),N($I5)>0),$I5,0)) | AI5: =IF(AND(NOT(AND($A5="",$B5="")),$K5="Point",N($L5)>0),SQRT(N($L5)/PI()),"") | AJ5: =IF(AND($A5="",$B5=""),"",IFERROR(VLOOKUP($G5,Lists!$D$4:$E$15,2,FALSE),"Not reported")) | AK5: =IF(AND($A5="",$B5=""),"",IF($X5<>"",$X5,IF($T5<>"Y","Not assessed",IF(AND(ISNUMBER($V5),Setup!$B$6-$V5>Setup!$B$26),"Assessment outdated",IF(NOT(ISNUMBER($W5)),"Assessed – no score",IF($W5>=Setup!$B$24,"High",IF($W5>=Setup!$B$25,"Moderate","Low"))))))) | AL5: =IF(AND($A5="",$B5=""),"",IF(Z5=0,"",IF(AND(AE5=1,N($R5)>AD5*1.01+0.001),"Net terrestrial > gross; ","")&IF(AND(AE5=1,N($S5)>AC5*1.01+0.001),"Net marine > gross; ","")&IF(AE5=0,"No net area – gross used, overlaps may be double-counted; ","")&IF(AH5=0,"STATUS_YR missing – imputed in time series; ","")&IF(AND(ISNUMBER($I5),N($I5)>Setup!$B$6),"STATUS_YR after reporting year; ","")&IF(OR($G5="",$G5="Not Reported"),"GOV_TYPE not reported; ","")&IF(AND(N($J5)=1,$K5="Point",N($M5)<=0),"Coastal point without REP_M_AREA – land/sea split unknown; ","")&IF(AND(N($J5)=0,N($S5)>0),"MARINE=0 but net marine >0; ","")&IF(AND(N($J5)=2,N($R5)>0),"MARINE=2 but net terrestrial >0; ","")&IF($K5="Point","Buffered point – coverage approximate; ","")))
A6: 4118 | B6: Djurdjura | C6: National Park | D6: National | E6: PA | F6: II | G6: Federal or national ministry or agency | H6: Designated | I6: 1983 | J6: 0 | K6: Polygon | L6: 185.5 | M6: 0 | N6: 202.167 | O6: 0 | P6: N | R6: 202.569 | S6: 0 | T6: Y | U6: METT | V6: 2013 | Y6: GD-PAME: Management Effectiveness Tracking Tool (METT) 2013; Biosphere Reserve Effectiveness of Management Index (BREMi) 2013 (from record 145569); Governance of Biodiversity Research Project (GOBI Survey) 2006 (from record 145569) | Z6: =IF(AND($A6="",$B6=""),"",IF(OR($E6="",$H6="",$H6="Proposed",$H6="Not Reported"),0,IF(AND($P6="Y",$Q6<>"Y"),0,IF(AND($K6="Point",N($L6)<=0),0,IF(AND(N($L6)<=0,N($N6)<=0,N($R6)+N($S6)<=0),0,1))))) | AA6: =IF(AND($A6="",$B6=""),"",IF($E6="","Site type missing",IF($H6="","STATUS missing",IF($H6="Proposed","STATUS = Proposed",IF($H6="Not Reported","STATUS = Not Reported",IF(AND($P6="Y",$Q6<>"Y"),"UNESCO-MAB Biosphere Reserve",IF(AND($K6="Point",N($L6)<=0),"Point without REP_AREA",IF(AND(N($L6)<=0,N($N6)<=0,N($R6)+N($S6)<=0),"No area information","")))))))) | AB6: =IF(AND($A6="",$B6=""),"",IF($K6="Point",N($L6),IF(N($N6)>0,N($N6),N($L6)))) | AC6: =IF(AND($A6="",$B6=""),"",MIN(AB6,IF(N($J6)=0,0,IF(N($J6)=2,AB6,IF(AND($K6<>"Point",N($O6)>0),N($O6),N($M6)))))) | AD6: =IF(AND($A6="",$B6=""),"",MAX(0,AB6-AC6)) | AE6: =IF(AND($A6="",$B6=""),"",IF(OR($R6<>"",$S6<>""),1,0)) | AF6: =IF(AND($A6="",$B6=""),"",IF(Z6=1,IF(AE6=1,N($R6),AD6),0)) | AG6: =IF(AND($A6="",$B6=""),"",IF(Z6=1,IF(AE6=1,N($S6),AC6),0)) | AH6: =IF(AND($A6="",$B6=""),"",IF(AND(ISNUMBER($I6),N($I6)>0),$I6,0)) | AI6: =IF(AND(NOT(AND($A6="",$B6="")),$K6="Point",N($L6)>0),SQRT(N($L6)/PI()),"") | AJ6: =IF(AND($A6="",$B6=""),"",IFERROR(VLOOKUP($G6,Lists!$D$4:$E$15,2,FALSE),"Not reported")) | AK6: =IF(AND($A6="",$B6=""),"",IF($X6<>"",$X6,IF($T6<>"Y","Not assessed",IF(AND(ISNUMBER($V6),Setup!$B$6-$V6>Setup!$B$26),"Assessment outdated",IF(NOT(ISNUMBER($W6)),"Assessed – no score",IF($W6>=Setup!$B$24,"High",IF($W6>=Setup!$B$25,"Moderate","Low"))))))) | AL6: =IF(AND($A6="",$B6=""),"",IF(Z6=0,"",IF(AND(AE6=1,N($R6)>AD6*1.01+0.001),"Net terrestrial > gross; ","")&IF(AND(AE6=1,N($S6)>AC6*1.01+0.001),"Net marine > gross; ","")&IF(AE6=0,"No net area – gross used, overlaps may be double-counted; ","")&IF(AH6=0,"STATUS_YR missing – imputed in time series; ","")&IF(AND(ISNUMBER($I6),N($I6)>Setup!$B$6),"STATUS_YR after reporting year; ","")&IF(OR($G6="",$G6="Not Reported"),"GOV_TYPE not reported; ","")&IF(AND(N($J6)=1,$K6="Point",N($M6)<=0),"Coastal point without REP_M_AREA – land/sea split unknown; ","")&IF(AND(N($J6)=0,N($S6)>0),"MARINE=0 but net marine >0; ","")&IF(AND(N($J6)=2,N($R6)>0),"MARINE=2 but net terrestrial >0; ","")&IF($K6="Point","Buffered point – coverage approximate; ","")))
A7: 9739 | B7: Théniet El Had | C7: National Park | D7: National | E7: PA | F7: II | G7: Federal or national ministry or agency | H7: Designated | I7: 1983 | J7: 0 | K7: Polygon | L7: 34.24 | M7: 0 | N7: 40.47 | O7: 0 | P7: N | R7: 40.556 | S7: 0 | T7: N | Z7: =IF(AND($A7="",$B7=""),"",IF(OR($E7="",$H7="",$H7="Proposed",$H7="Not Reported"),0,IF(AND($P7="Y",$Q7<>"Y"),0,IF(AND($K7="Point",N($L7)<=0),0,IF(AND(N($L7)<=0,N($N7)<=0,N($R7)+N($S7)<=0),0,1))))) | AA7: =IF(AND($A7="",$B7=""),"",IF($E7="","Site type missing",IF($H7="","STATUS missing",IF($H7="Proposed","STATUS = Proposed",IF($H7="Not Reported","STATUS = Not Reported",IF(AND($P7="Y",$Q7<>"Y"),"UNESCO-MAB Biosphere Reserve",IF(AND($K7="Point",N($L7)<=0),"Point without REP_AREA",IF(AND(N($L7)<=0,N($N7)<=0,N($R7)+N($S7)<=0),"No area information","")))))))) | AB7: =IF(AND($A7="",$B7=""),"",IF($K7="Point",N($L7),IF(N($N7)>0,N($N7),N($L7)))) | AC7: =IF(AND($A7="",$B7=""),"",MIN(AB7,IF(N($J7)=0,0,IF(N($J7)=2,AB7,IF(AND($K7<>"Point",N($O7)>0),N($O7),N($M7)))))) | AD7: =IF(AND($A7="",$B7=""),"",MAX(0,AB7-AC7)) | AE7: =IF(AND($A7="",$B7=""),"",IF(OR($R7<>"",$S7<>""),1,0)) | AF7: =IF(AND($A7="",$B7=""),"",IF(Z7=1,IF(AE7=1,N($R7),AD7),0)) | AG7: =IF(AND($A7="",$B7=""),"",IF(Z7=1,IF(AE7=1,N($S7),AC7),0)) | AH7: =IF(AND($A7="",$B7=""),"",IF(AND(ISNUMBER($I7),N($I7)>0),$I7,0)) | AI7: =IF(AND(NOT(AND($A7="",$B7="")),$K7="Point",N($L7)>0),SQRT(N($L7)/PI()),"") | AJ7: =IF(AND($A7="",$B7=""),"",IFERROR(VLOOKUP($G7,Lists!$D$4:$E$15,2,FALSE),"Not reported")) | AK7: =IF(AND($A7="",$B7=""),"",IF($X7<>"",$X7,IF($T7<>"Y","Not assessed",IF(AND(ISNUMBER($V7),Setup!$B$6-$V7>Setup!$B$26),"Assessment outdated",IF(NOT(ISNUMBER($W7)),"Assessed – no score",IF($W7>=Setup!$B$24,"High",IF($W7>=Setup!$B$25,"Moderate","Low"))))))) | AL7: =IF(AND($A7="",$B7=""),"",IF(Z7=0,"",IF(AND(AE7=1,N($R7)>AD7*1.01+0.001),"Net terrestrial > gross; ","")&IF(AND(AE7=1,N($S7)>AC7*1.01+0.001),"Net marine > gross; ","")&IF(AE7=0,"No net area – gross used, overlaps may be double-counted; ","")&IF(AH7=0,"STATUS_YR missing – imputed in time series; ","")&IF(AND(ISNUMBER($I7),N($I7)>Setup!$B$6),"STATUS_YR after reporting year; ","")&IF(OR($G7="",$G7="Not Reported"),"GOV_TYPE not reported; ","")&IF(AND(N($J7)=1,$K7="Point",N($M7)<=0),"Coastal point without REP_M_AREA – land/sea split unknown; ","")&IF(AND(N($J7)=0,N($S7)>0),"MARINE=0 but net marine >0; ","")&IF(AND(N($J7)=2,N($R7)>0),"MARINE=2 but net terrestrial >0; ","")&IF($K7="Point","Buffered point – coverage approximate; ","")))
A8: 9740 | B8: Chréa | C8: National Park | D8: National | E8: PA | F8: II | G8: Federal or national ministry or agency | H8: Designated | I8: 1983 | J8: 0 | K8: Polygon | L8: 265.87 | M8: 0 | N8: 276.858 | O8: 0 | P8: N | R8: 277.412 | S8: 0 | T8: Y | U8: Other | V8: 2013 | Y8: GD-PAME: Biosphere Reserve Effectiveness of Management Index (BREMi) 2013 (from record 900713) | Z8: =IF(AND($A8="",$B8=""),"",IF(OR($E8="",$H8="",$H8="Proposed",$H8="Not Reported"),0,IF(AND($P8="Y",$Q8<>"Y"),0,IF(AND($K8="Point",N($L8)<=0),0,IF(AND(N($L8)<=0,N($N8)<=0,N($R8)+N($S8)<=0),0,1))))) | AA8: =IF(AND($A8="",$B8=""),"",IF($E8="","Site type missing",IF($H8="","STATUS missing",IF($H8="Proposed","STATUS = Proposed",IF($H8="Not Reported","STATUS = Not Reported",IF(AND($P8="Y",$Q8<>"Y"),"UNESCO-MAB Biosphere Reserve",IF(AND($K8="Point",N($L8)<=0),"Point without REP_AREA",IF(AND(N($L8)<=0,N($N8)<=0,N($R8)+N($S8)<=0),"No area information","")))))))) | AB8: =IF(AND($A8="",$B8=""),"",IF($K8="Point",N($L8),IF(N($N8)>0,N($N8),N($L8)))) | AC8: =IF(AND($A8="",$B8=""),"",MIN(AB8,IF(N($J8)=0,0,IF(N($J8)=2,AB8,IF(AND($K8<>"Point",N($O8)>0),N($O8),N($M8)))))) | AD8: =IF(AND($A8="",$B8=""),"",MAX(0,AB8-AC8)) | AE8: =IF(AND($A8="",$B8=""),"",IF(OR($R8<>"",$S8<>""),1,0)) | AF8: =IF(AND($A8="",$B8=""),"",IF(Z8=1,IF(AE8=1,N($R8),AD8),0)) | AG8: =IF(AND($A8="",$B8=""),"",IF(Z8=1,IF(AE8=1,N($S8),AC8),0)) | AH8: =IF(AND($A8="",$B8=""),"",IF(AND(ISNUMBER($I8),N($I8)>0),$I8,0)) | AI8: =IF(AND(NOT(AND($A8="",$B8="")),$K8="Point",N($L8)>0),SQRT(N($L8)/PI()),"") | AJ8: =IF(AND($A8="",$B8=""),"",IFERROR(VLOOKUP($G8,Lists!$D$4:$E$15,2,FALSE),"Not reported")) | AK8: =IF(AND($A8="",$B8=""),"",IF($X8<>"",$X8,IF($T8<>"Y","Not assessed",IF(AND(ISNUMBER($V8),Setup!$B$6-$V8>Setup!$B$26),"Assessment outdated",IF(NOT(ISNUMBER($W8)),"Assessed – no score",IF($W8>=Setup!$B$24,"High",IF($W8>=Setup!$B$25,"Moderate","Low"))))))) | AL8: =IF(AND($A8="",$B8=""),"",IF(Z8=0,"",IF(AND(AE8=1,N($R8)>AD8*1.01+0.001),"Net terrestrial > gross; ","")&IF(AND(AE8=1,N($S8)>AC8*1.01+0.001),"Net marine > gross; ","")&IF(AE8=0,"No net area – gross used, overlaps may be double-counted; ","")&IF(AH8=0,"STATUS_YR missing – imputed in time series; ","")&IF(AND(ISNUMBER($I8),N($I8)>Setup!$B$6),"STATUS_YR after reporting year; ","")&IF(OR($G8="",$G8="Not Reported"),"GOV_TYPE not reported; ","")&IF(AND(N($J8)=1,$K8="Point",N($M8)<=0),"Coastal point without REP_M_AREA – land/sea split unknown; ","")&IF(AND(N($J8)=0,N($S8)>0),"MARINE=0 but net marine >0; ","")&IF(AND(N($J8)=2,N($R8)>0),"MARINE=2 but net terrestrial >0; ","")&IF($K8="Point","Buffered point – coverage approximate; ","")))
A9: 9741 | B9: El Kala | C9: National Park | D9: National | E9: PA | F9: II | G9: Federal or national ministry or agency | H9: Designated | I9: 1983 | J9: 0 | K9: Polygon | L9: 764.38 | M9: 32.09 | N9: 776.954 | O9: 0.816 | P9: N | R9: 772.875 | S9: 0.542 | T9: Y | U9: Other | V9: 2013 | Y9: GD-PAME: Biosphere Reserve Effectiveness of Management Index (BREMi) 2013 (from record 26620) | Z9: =IF(AND($A9="",$B9=""),"",IF(OR($E9="",$H9="",$H9="Proposed",$H9="Not Reported"),0,IF(AND($P9="Y",$Q9<>"Y"),0,IF(AND($K9="Point",N($L9)<=0),0,IF(AND(N($L9)<=0,N($N9)<=0,N($R9)+N($S9)<=0),0,1))))) | AA9: =IF(AND($A9="",$B9=""),"",IF($E9="","Site type missing",IF($H9="","STATUS missing",IF($H9="Proposed","STATUS = Proposed",IF($H9="Not Reported","STATUS = Not Reported",IF(AND($P9="Y",$Q9<>"Y"),"UNESCO-MAB Biosphere Reserve",IF(AND($K9="Point",N($L9)<=0),"Point without REP_AREA",IF(AND(N($L9)<=0,N($N9)<=0,N($R9)+N($S9)<=0),"No area information","")))))))) | AB9: =IF(AND($A9="",$B9=""),"",IF($K9="Point",N($L9),IF(N($N9)>0,N($N9),N($L9)))) | AC9: =IF(AND($A9="",$B9=""),"",MIN(AB9,IF(N($J9)=0,0,IF(N($J9)=2,AB9,IF(AND($K9<>"Point",N($O9)>0),N($O9),N($M9)))))) | AD9: =IF(AND($A9="",$B9=""),"",MAX(0,AB9-AC9)) | AE9: =IF(AND($A9="",$B9=""),"",IF(OR($R9<>"",$S9<>""),1,0)) | AF9: =IF(AND($A9="",$B9=""),"",IF(Z9=1,IF(AE9=1,N($R9),AD9),0)) | AG9: =IF(AND($A9="",$B9=""),"",IF(Z9=1,IF(AE9=1,N($S9),AC9),0)) | AH9: =IF(AND($A9="",$B9=""),"",IF(AND(ISNUMBER($I9),N($I9)>0),$I9,0)) | AI9: =IF(AND(NOT(AND($A9="",$B9="")),$K9="Point",N($L9)>0),SQRT(N($L9)/PI()),"") | AJ9: =IF(AND($A9="",$B9=""),"",IFERROR(VLOOKUP($G9,Lists!$D$4:$E$15,2,FALSE),"Not reported")) | AK9: =IF(AND($A9="",$B9=""),"",IF($X9<>"",$X9,IF($T9<>"Y","Not assessed",IF(AND(ISNUMBER($V9),Setup!$B$6-$V9>Setup!$B$26),"Assessment outdated",IF(NOT(ISNUMBER($W9)),"Assessed – no score",IF($W9>=Setup!$B$24,"High",IF($W9>=Setup!$B$25,"Moderate","Low"))))))) | AL9: =IF(AND($A9="",$B9=""),"",IF(Z9=0,"",IF(AND(AE9=1,N($R9)>AD9*1.01+0.001),"Net terrestrial > gross; ","")&IF(AND(AE9=1,N($S9)>AC9*1.01+0.001),"Net marine > gross; ","")&IF(AE9=0,"No net area – gross used, overlaps may be double-counted; ","")&IF(AH9=0,"STATUS_YR missing – imputed in time series; ","")&IF(AND(ISNUMBER($I9),N($I9)>Setup!$B$6),"STATUS_YR after reporting year; ","")&IF(OR($G9="",$G9="Not Reported"),"GOV_TYPE not reported; ","")&IF(AND(N($J9)=1,$K9="Point",N($M9)<=0),"Coastal point without REP_M_AREA – land/sea split unknown; ","")&IF(AND(N($J9)=0,N($S9)>0),"MARINE=0 but net marine >0; ","")&IF(AND(N($J9)=2,N($R9)>0),"MARINE=2 but net terrestrial >0; ","")&IF($K9="Point","Buffered point – coverage approximate; ","")))
A10: 17706 | B10: Réserve Intégrale du Lac Oubeïra | C10: Wetland of International Importance (Ramsar Site) | D10: International | E10: PA | F10: Not Reported | G10: Federal or national ministry or agency | H10: Designated | I10: 1983 | J10: 0 | K10: Polygon | L10: 22 | M10: 0 | N10: 24.051 | O10: 0 | P10: N | R10: 0 | S10: 0 | T10: Y | U10: Other | V10: 2001 | Y10: GD-PAME: Birdlife Important Bird and Biodiversity Area Monitoring (Birdlife IBA) 2001; Overlap attributed to earlier site | Z10: =IF(AND($A10="",$B10=""),"",IF(OR($E10="",$H10="",$H10="Proposed",$H10="Not Reported"),0,IF(AND($P10="Y",$Q10<>"Y"),0,IF(AND($K10="Point",N($L10)<=0),0,IF(AND(N($L10)<=0,N($N10)<=0,N($R10)+N($S10)<=0),0,1))))) | AA10: =IF(AND($A10="",$B10=""),"",IF($E10="","Site type missing",IF($H10="","STATUS missing",IF($H10="Proposed","STATUS = Proposed",IF($H10="Not Reported","STATUS = Not Reported",IF(AND($P10="Y",$Q10<>"Y"),"UNESCO-MAB Biosphere Reserve",IF(AND($K10="Point",N($L10)<=0),"Point without REP_AREA",IF(AND(N($L10)<=0,N($N10)<=0,N($R10)+N($S10)<=0),"No area information","")))))))) | AB10: =IF(AND($A10="",$B10=""),"",IF($K10="Point",N($L10),IF(N($N10)>0,N($N10),N($L10)))) | AC10: =IF(AND($A10="",$B10=""),"",MIN(AB10,IF(N($J10)=0,0,IF(N($J10)=2,AB10,IF(AND($K10<>"Point",N($O10)>0),N($O10),N($M10)))))) | AD10: =IF(AND($A10="",$B10=""),"",MAX(0,AB10-AC10)) | AE10: =IF(AND($A10="",$B10=""),"",IF(OR($R10<>"",$S10<>""),1,0)) | AF10: =IF(AND($A10="",$B10=""),"",IF(Z10=1,IF(AE10=1,N($R10),AD10),0)) | AG10: =IF(AND($A10="",$B10=""),"",IF(Z10=1,IF(AE10=1,N($S10),AC10),0)) | AH10: =IF(AND($A10="",$B10=""),"",IF(AND(ISNUMBER($I10),N($I10)>0),$I10,0)) | AI10: =IF(AND(NOT(AND($A10="",$B10="")),$K10="Point",N($L10)>0),SQRT(N($L10)/PI()),"") | AJ10: =IF(AND($A10="",$B10=""),"",IFERROR(VLOOKUP($G10,Lists!$D$4:$E$15,2,FALSE),"Not reported")) | AK10: =IF(AND($A10="",$B10=""),"",IF($X10<>"",$X10,IF($T10<>"Y","Not assessed",IF(AND(ISNUMBER($V10),Setup!$B$6-$V10>Setup!$B$26),"Assessment outdated",IF(NOT(ISNUMBER($W10)),"Assessed – no score",IF($W10>=Setup!$B$24,"High",IF($W10>=Setup!$B$25,"Moderate","Low"))))))) | AL10: =IF(AND($A10="",$B10=""),"",IF(Z10=0,"",IF(AND(AE10=1,N($R10)>AD10*1.01+0.001),"Net terrestrial > gross; ","")&IF(AND(AE10=1,N($S10)>AC10*1.01+0.001),"Net marine > gross; ","")&IF(AE10=0,"No net area – gross used, overlaps may be double-counted; ","")&IF(AH10=0,"STATUS_YR missing – imputed in time series; ","")&IF(AND(ISNUMBER($I10),N($I10)>Setup!$B$6),"STATUS_YR after reporting year; ","")&IF(OR($G10="",$G10="Not Reported"),"GOV_TYPE not reported; ","")&IF(AND(N($J10)=1,$K10="Point",N($M10)<=0),"Coastal point without REP_M_AREA – land/sea split unknown; ","")&IF(AND(N($J10)=0,N($S10)>0),"MARINE=0 but net marine >0; ","")&IF(AND(N($J10)=2,N($R10)>0),"MARINE=2 but net terrestrial >0; ","")&IF($K10="Point","Buffered point – coverage approximate; ","")))
A11: 67756 | B11: Réserve Intégrale du Lac Tonga | C11: Wetland of International Importance (Ramsar Site) | D11: International | E11: PA | F11: Not Reported | G11: Federal or national ministry or agency | H11: Designated | I11: 1983 | J11: 0 | K11: Polygon | L11: 27 | M11: 0 | N11: 52.833 | O11: 0.148 | P11: N | R11: 0.098 | S11: 0.109 | T11: Y | U11: Other | V11: 2001 | Y11: GD-PAME: Birdlife Important Bird and Biodiversity Area Monitoring (Birdlife IBA) 2001; Overlap attributed to earlier site | Z11: =IF(AND($A11="",$B11=""),"",IF(OR($E11="",$H11="",$H11="Proposed",$H11="Not Reported"),0,IF(AND($P11="Y",$Q11<>"Y"),0,IF(AND($K11="Point",N($L11)<=0),0,IF(AND(N($L11)<=0,N($N11)<=0,N($R11)+N($S11)<=0),0,1))))) | AA11: =IF(AND($A11="",$B11=""),"",IF($E11="","Site type missing",IF($H11="","STATUS missing",IF($H11="Proposed","STATUS = Proposed",IF($H11="Not Reported","STATUS = Not Reported",IF(AND($P11="Y",$Q11<>"Y"),"UNESCO-MAB Biosphere Reserve",IF(AND($K11="Point",N($L11)<=0),"Point without REP_AREA",IF(AND(N($L11)<=0,N($N11)<=0,N($R11)+N($S11)<=0),"No area information","")))))))) | AB11: =IF(AND($A11="",$B11=""),"",IF($K11="Point",N($L11),IF(N($N11)>0,N($N11),N($L11)))) | AC11: =IF(AND($A11="",$B11=""),"",MIN(AB11,IF(N($J11)=0,0,IF(N($J11)=2,AB11,IF(AND($K11<>"Point",N($O11)>0),N($O11),N($M11)))))) | AD11: =IF(AND($A11="",$B11=""),"",MAX(0,AB11-AC11)) | AE11: =IF(AND($A11="",$B11=""),"",IF(OR($R11<>"",$S11<>""),1,0)) | AF11: =IF(AND($A11="",$B11=""),"",IF(Z11=1,IF(AE11=1,N($R11),AD11),0)) | AG11: =IF(AND($A11="",$B11=""),"",IF(Z11=1,IF(AE11=1,N($S11),AC11),0)) | AH11: =IF(AND($A11="",$B11=""),"",IF(AND(ISNUMBER($I11),N($I11)>0),$I11,0)) | AI11: =IF(AND(NOT(AND($A11="",$B11="")),$K11="Point",N($L11)>0),SQRT(N($L11)/PI()),"") | AJ11: =IF(AND($A11="",$B11=""),"",IFERROR(VLOOKUP($G11,Lists!$D$4:$E$15,2,FALSE),"Not reported")) | AK11: =IF(AND($A11="",$B11=""),"",IF($X11<>"",$X11,IF($T11<>"Y","Not assessed",IF(AND(ISNUMBER($V11),Setup!$B$6-$V11>Setup!$B$26),"Assessment outdated",IF(NOT(ISNUMBER($W11)),"Assessed – no score",IF($W11>=Setup!$B$24,"High",IF($W11>=Setup!$B$25,"Moderate","Low"))))))) | AL11: =IF(AND($A11="",$B11=""),"",IF(Z11=0,"",IF(AND(AE11=1,N($R11)>AD11*1.01+0.001),"Net terrestrial > gross; ","")&IF(AND(AE11=1,N($S11)>AC11*1.01+0.001),"Net marine > gross; ","")&IF(AE11=0,"No net area – gross used, overlaps may be double-counted; ","")&IF(AH11=0,"STATUS_YR missing – imputed in time series; ","")&IF(AND(ISNUMBER($I11),N($I11)>Setup!$B$6),"STATUS_YR after reporting year; ","")&IF(OR($G11="",$G11="Not Reported"),"GOV_TYPE not reported; ","")&IF(AND(N($J11)=1,$K11="Point",N($M11)<=0),"Coastal point without REP_M_AREA – land/sea split unknown; ","")&IF(AND(N($J11)=0,N($S11)>0),"MARINE=0 but net marine >0; ","")&IF(AND(N($J11)=2,N($R11)>0),"MARINE=2 but net terrestrial >0; ","")&IF($K11="Point","Buffered point – coverage approximate; ","")))
A12: 9742 | B12: Belezma | C12: National Park | D12: National | E12: PA | F12: II | G12: Federal or national ministry or agency | H12: Designated | I12: 1984 | J12: 0 | K12: Polygon | L12: 262.5 | M12: 0 | N12: 272.123 | O12: 0 | P12: N | R12: 272.716 | S12: 0 | T12: N | Z12: =IF(AND($A12="",$B12=""),"",IF(OR($E12="",$H12="",$H12="Proposed",$H12="Not Reported"),0,IF(AND($P12="Y",$Q12<>"Y"),0,IF(AND($K12="Point",N($L12)<=0),0,IF(AND(N($L12)<=0,N($N12)<=0,N($R12)+N($S12)<=0),0,1))))) | AA12: =IF(AND($A12="",$B12=""),"",IF($E12="","Site type missing",IF($H12="","STATUS missing",IF($H12="Proposed","STATUS = Proposed",IF($H12="Not Reported","STATUS = Not Reported",IF(AND($P12="Y",$Q12<>"Y"),"UNESCO-MAB Biosphere Reserve",IF(AND($K12="Point",N($L12)<=0),"Point without REP_AREA",IF(AND(N($L12)<=0,N($N12)<=0,N($R12)+N($S12)<=0),"No area information","")))))))) | AB12: =IF(AND($A12="",$B12=""),"",IF($K12="Point",N($L12),IF(N($N12)>0,N($N12),N($L12)))) | AC12: =IF(AND($A12="",$B12=""),"",MIN(AB12,IF(N($J12)=0,0,IF(N($J12)=2,AB12,IF(AND($K12<>"Point",N($O12)>0),N($O12),N($M12)))))) | AD12: =IF(AND($A12="",$B12=""),"",MAX(0,AB12-AC12)) | AE12: =IF(AND($A12="",$B12=""),"",IF(OR($R12<>"",$S12<>""),1,0)) | AF12: =IF(AND($A12="",$B12=""),"",IF(Z12=1,IF(AE12=1,N($R12),AD12),0)) | AG12: =IF(AND($A12="",$B12=""),"",IF(Z12=1,IF(AE12=1,N($S12),AC12),0)) | AH12: =IF(AND($A12="",$B12=""),"",IF(AND(ISNUMBER($I12),N($I12)>0),$I12,0)) | AI12: =IF(AND(NOT(AND($A12="",$B12="")),$K12="Point",N($L12)>0),SQRT(N($L12)/PI()),"") | AJ12: =IF(AND($A12="",$B12=""),"",IFERROR(VLOOKUP($G12,Lists!$D$4:$E$15,2,FALSE),"Not reported")) | AK12: =IF(AND($A12="",$B12=""),"",IF($X12<>"",$X12,IF($T12<>"Y","Not assessed",IF(AND(ISNUMBER($V12),Setup!$B$6-$V12>Setup!$B$26),"Assessment outdated",IF(NOT(ISNUMBER($W12)),"Assessed – no score",IF($W12>=Setup!$B$24,"High",IF($W12>=Setup!$B$25,"Moderate","Low"))))))) | AL12: =IF(AND($A12="",$B12=""),"",IF(Z12=0,"",IF(AND(AE12=1,N($R12)>AD12*1.01+0.001),"Net terrestrial > gross; ","")&IF(AND(AE12=1,N($S12)>AC12*1.01+0.001),"Net marine > gross; ","")&IF(AE12=0,"No net area – gross used, overlaps may be double-counted; ","")&IF(AH12=0,"STATUS_YR missing – imputed in time series; ","")&IF(AND(ISNUMBER($I12),N($I12)>Setup!$B$6),"STATUS_YR after reporting year; ","")&IF(OR($G12="",$G12="Not Reported"),"GOV_TYPE not reported; ","")&IF(AND(N($J12)=1,$K12="Point",N($M12)<=0),"Coastal point without REP_M_AREA – land/sea split unknown; ","")&IF(AND(N($J12)=0,N($S12)>0),"MARINE=0 but net marine >0; ","")&IF(AND(N($J12)=2,N($R12)>0),"MARINE=2 but net terrestrial >0; ","")&IF($K12="Point","Buffered point – coverage approximate; ","")))
A13: 9743 | B13: Taza | C13: National Park | D13: National | E13: PA | F13: II | G13: Federal or national ministry or agency | H13: Designated | I13: 1984 | J13: 0 | K13: Polygon | L13: 38.07 | M13: 8.97 | N13: 41.155 | O13: 0.502 | P13: N | R13: 41.069 | S13: 0.165 | T13: Y | U13: Other | V13: 2013 | Y13: GD-PAME: Biosphere Reserve Effectiveness of Management Index (BREMi) 2013 (from record 902530); Governance of Biodiversity Research Project (GOBI Survey) 2006 (from record 902530) | Z13: =IF(AND($A13="",$B13=""),"",IF(OR($E13="",$H13="",$H13="Proposed",$H13="Not Reported"),0,IF(AND($P13="Y",$Q13<>"Y"),0,IF(AND($K13="Point",N($L13)<=0),0,IF(AND(N($L13)<=0,N($N13)<=0,N($R13)+N($S13)<=0),0,1))))) | AA13: =IF(AND($A13="",$B13=""),"",IF($E13="","Site type missing",IF($H13="","STATUS missing",IF($H13="Proposed","STATUS = Proposed",IF($H13="Not Reported","STATUS = Not Reported",IF(AND($P13="Y",$Q13<>"Y"),"UNESCO-MAB Biosphere Reserve",IF(AND($K13="Point",N($L13)<=0),"Point without REP_AREA",IF(AND(N($L13)<=0,N($N13)<=0,N($R13)+N($S13)<=0),"No area information","")))))))) | AB13: =IF(AND($A13="",$B13=""),"",IF($K13="Point",N($L13),IF(N($N13)>0,N($N13),N($L13)))) | AC13: =IF(AND($A13="",$B13=""),"",MIN(AB13,IF(N($J13)=0,0,IF(N($J13)=2,AB13,IF(AND($K13<>"Point",N($O13)>0),N($O13),N($M13)))))) | AD13: =IF(AND($A13="",$B13=""),"",MAX(0,AB13-AC13)) | AE13: =IF(AND($A13="",$B13=""),"",IF(OR($R13<>"",$S13<>""),1,0)) | AF13: =IF(AND($A13="",$B13=""),"",IF(Z13=1,IF(AE13=1,N($R13),AD13),0)) | AG13: =IF(AND($A13="",$B13=""),"",IF(Z13=1,IF(AE13=1,N($S13),AC13),0)) | AH13: =IF(AND($A13="",$B13=""),"",IF(AND(ISNUMBER($I13),N($I13)>0),$I13,0)) | AI13: =IF(AND(NOT(AND($A13="",$B13="")),$K13="Point",N($L13)>0),SQRT(N($L13)/PI()),"") | AJ13: =IF(AND($A13="",$B13=""),"",IFERROR(VLOOKUP($G13,Lists!$D$4:$E$15,2,FALSE),"Not reported")) | AK13: =IF(AND($A13="",$B13=""),"",IF($X13<>"",$X13,IF($T13<>"Y","Not assessed",IF(AND(ISNUMBER($V13),Setup!$B$6-$V13>Setup!$B$26),"Assessment outdated",IF(NOT(ISNUMBER($W13)),"Assessed – no score",IF($W13>=Setup!$B$24,"High",IF($W13>=Setup!$B$25,"Moderate","Low"))))))) | AL13: =IF(AND($A13="",$B13=""),"",IF(Z13=0,"",IF(AND(AE13=1,N($R13)>AD13*1.01+0.001),"Net terrestrial > gross; ","")&IF(AND(AE13=1,N($S13)>AC13*1.01+0.001),"Net marine > gross; ","")&IF(AE13=0,"No net area – gross used, overlaps may be double-counted; ","")&IF(AH13=0,"STATUS_YR missing – imputed in time series; ","")&IF(AND(ISNUMBER($I13),N($I13)>Setup!$B$6),"STATUS_YR after reporting year; ","")&IF(OR($G13="",$G13="Not Reported"),"GOV_TYPE not reported; ","")&IF(AND(N($J13)=1,$K13="Point",N($M13)<=0),"Coastal point without REP_M_AREA – land/sea split unknown; ","")&IF(AND(N($J13)=0,N($S13)>0),"MARINE=0 but net marine >0; ","")&IF(AND(N($J13)=2,N($R13)>0),"MARINE=2 but net terrestrial >0; ","")&IF($K13="Point","Buffered point – coverage approximate; ","")))
A14: 9747 | B14: Gouraya | C14: National Park | D14: National | E14: PA | F14: II | G14: Federal or national ministry or agency | H14: Designated | I14: 1984 | J14: 0 | K14: Polygon | L14: 20.8 | M14: 10.21 | N14: 21.2 | O14: 1.195 | P14: N | R14: 21.039 | S14: 0.202 | T14: Y | U14: Other | V14: 2013 | Y14: GD-PAME: Biosphere Reserve Effectiveness of Management Index (BREMi) 2013 (from record 902531); Governance of Biodiversity Research Project (GOBI Survey) 2006 (from record 902531) | Z14: =IF(AND($A14="",$B14=""),"",IF(OR($E14="",$H14="",$H14="Proposed",$H14="Not Reported"),0,IF(AND($P14="Y",$Q14<>"Y"),0,IF(AND($K14="Point",N($L14)<=0),0,IF(AND(N($L14)<=0,N($N14)<=0,N($R14)+N($S14)<=0),0,1))))) | AA14: =IF(AND($A14="",$B14=""),"",IF($E14="","Site type missing",IF($H14="","STATUS missing",IF($H14="Proposed","STATUS = Proposed",IF($H14="Not Reported","STATUS = Not Reported",IF(AND($P14="Y",$Q14<>"Y"),"UNESCO-MAB Biosphere Reserve",IF(AND($K14="Point",N($L14)<=0),"Point without REP_AREA",IF(AND(N($L14)<=0,N($N14)<=0,N($R14)+N($S14)<=0),"No area information","")))))))) | AB14: =IF(AND($A14="",$B14=""),"",IF($K14="Point",N($L14),IF(N($N14)>0,N($N14),N($L14)))) | AC14: =IF(AND($A14="",$B14=""),"",MIN(AB14,IF(N($J14)=0,0,IF(N($J14)=2,AB14,IF(AND($K14<>"Point",N($O14)>0),N($O14),N($M14)))))) | AD14: =IF(AND($A14="",$B14=""),"",MAX(0,AB14-AC14)) | AE14: =IF(AND($A14="",$B14=""),"",IF(OR($R14<>"",$S14<>""),1,0)) | AF14: =IF(AND($A14="",$B14=""),"",IF(Z14=1,IF(AE14=1,N($R14),AD14),0)) | AG14: =IF(AND($A14="",$B14=""),"",IF(Z14=1,IF(AE14=1,N($S14),AC14),0)) | AH14: =IF(AND($A14="",$B14=""),"",IF(AND(ISNUMBER($I14),N($I14)>0),$I14,0)) | AI14: =IF(AND(NOT(AND($A14="",$B14="")),$K14="Point",N($L14)>0),SQRT(N($L14)/PI()),"") | AJ14: =IF(AND($A14="",$B14=""),"",IFERROR(VLOOKUP($G14,Lists!$D$4:$E$15,2,FALSE),"Not reported")) | AK14: =IF(AND($A14="",$B14=""),"",IF($X14<>"",$X14,IF($T14<>"Y","Not assessed",IF(AND(ISNUMBER($V14),Setup!$B$6-$V14>Setup!$B$26),"Assessment outdated",IF(NOT(ISNUMBER($W14)),"Assessed – no score",IF($W14>=Setup!$B$24,"High",IF($W14>=Setup!$B$25,"Moderate","Low"))))))) | AL14: =IF(AND($A14="",$B14=""),"",IF(Z14=0,"",IF(AND(AE14=1,N($R14)>AD14*1.01+0.001),"Net terrestrial > gross; ","")&IF(AND(AE14=1,N($S14)>AC14*1.01+0.001),"Net marine > gross; ","")&IF(AE14=0,"No net area – gross used, overlaps may be double-counted; ","")&IF(AH14=0,"STATUS_YR missing – imputed in time series; ","")&IF(AND(ISNUMBER($I14),N($I14)>Setup!$B$6),"STATUS_YR after reporting year; ","")&IF(OR($G14="",$G14="Not Reported"),"GOV_TYPE not reported; ","")&IF(AND(N($J14)=1,$K14="Point",N($M14)<=0),"Coastal point without REP_M_AREA – land/sea split unknown; ","")&IF(AND(N($J14)=0,N($S14)>0),"MARINE=0 but net marine >0; ","")&IF(AND(N($J14)=2,N($R14)>0),"MARINE=2 but net terrestrial >0; ","")&IF($K14="Point","Buffered point – coverage approximate; ","")))
A15: 20389 | B15: Tassili N'Ajjer | C15: UNESCO-MAB Biosphere Reserve | D15: International | E15: PA | F15: Not Applicable | G15: Not Reported | H15: Designated | I15: 1986 | J15: 0 | K15: Polygon | L15: 72000 | M15: 0 | N15: 98902.485 | O15: 0 | P15: Y | T15: N | Y15: Excluded in GIS: UNESCO-MAB Biosphere Reserve | Z15: =IF(AND($A15="",$B15=""),"",IF(OR($E15="",$H15="",$H15="Proposed",$H15="Not Reported"),0,IF(AND($P15="Y",$Q15<>"Y"),0,IF(AND($K15="Point",N($L15)<=0),0,IF(AND(N($L15)<=0,N($N15)<=0,N($R15)+N($S15)<=0),0,1))))) | AA15: =IF(AND($A15="",$B15=""),"",IF($E15="","Site type missing",IF($H15="","STATUS missing",IF($H15="Proposed","STATUS = Proposed",IF($H15="Not Reported","STATUS = Not Reported",IF(AND($P15="Y",$Q15<>"Y"),"UNESCO-MAB Biosphere Reserve",IF(AND($K15="Point",N($L15)<=0),"Point without REP_AREA",IF(AND(N($L15)<=0,N($N15)<=0,N($R15)+N($S15)<=0),"No area information","")))))))) | AB15: =IF(AND($A15="",$B15=""),"",IF($K15="Point",N($L15),IF(N($N15)>0,N($N15),N($L15)))) | AC15: =IF(AND($A15="",$B15=""),"",MIN(AB15,IF(N($J15)=0,0,IF(N($J15)=2,AB15,IF(AND($K15<>"Point",N($O15)>0),N($O15),N($M15)))))) | AD15: =IF(AND($A15="",$B15=""),"",MAX(0,AB15-AC15)) | AE15: =IF(AND($A15="",$B15=""),"",IF(OR($R15<>"",$S15<>""),1,0)) | AF15: =IF(AND($A15="",$B15=""),"",IF(Z15=1,IF(AE15=1,N($R15),AD15),0)) | AG15: =IF(AND($A15="",$B15=""),"",IF(Z15=1,IF(AE15=1,N($S15),AC15),0)) | AH15: =IF(AND($A15="",$B15=""),"",IF(AND(ISNUMBER($I15),N($I15)>0),$I15,0)) | AI15: =IF(AND(NOT(AND($A15="",$B15="")),$K15="Point",N($L15)>0),SQRT(N($L15)/PI()),"") | AJ15: =IF(AND($A15="",$B15=""),"",IFERROR(VLOOKUP($G15,Lists!$D$4:$E$15,2,FALSE),"Not reported")) | AK15: =IF(AND($A15="",$B15=""),"",IF($X15<>"",$X15,IF($T15<>"Y","Not assessed",IF(AND(ISNUMBER($V15),Setup!$B$6-$V15>Setup!$B$26),"Assessment outdated",IF(NOT(ISNUMBER($W15)),"Assessed – no score",IF($W15>=Setup!$B$24,"High",IF($W15>=Setup!$B$25,"Moderate","Low"))))))) | AL15: =IF(AND($A15="",$B15=""),"",IF(Z15=0,"",IF(AND(AE15=1,N($R15)>AD15*1.01+0.001),"Net terrestrial > gross; ","")&IF(AND(AE15=1,N($S15)>AC15*1.01+0.001),"Net marine > gross; ","")&IF(AE15=0,"No net area – gross used, overlaps may be double-counted; ","")&IF(AH15=0,"STATUS_YR missing – imputed in time series; ","")&IF(AND(ISNUMBER($I15),N($I15)>Setup!$B$6),"STATUS_YR after reporting year; ","")&IF(OR($G15="",$G15="Not Reported"),"GOV_TYPE not reported; ","")&IF(AND(N($J15)=1,$K15="Point",N($M15)<=0),"Coastal point without REP_M_AREA – land/sea split unknown; ","")&IF(AND(N($J15)=0,N($S15)>0),"MARINE=0 but net marine >0; ","")&IF(AND(N($J15)=2,N($R15)>0),"MARINE=2 but net terrestrial >0; ","")&IF($K15="Point","Buffered point – coverage approximate; ","")))
A16: 26620 | B16: El Kala | C16: UNESCO-MAB Biosphere Reserve | D16: International | E16: PA | F16: Not Applicable | G16: Not Reported | H16: Designated | I16: 1990 | J16: 0 | K16: Polygon | L16: 764.38 | M16: 0 | N16: 776.954 | O16: 0.816 | P16: Y | T16: N | Y16: Excluded in GIS: UNESCO-MAB Biosphere Reserve | Z16: =IF(AND($A16="",$B16=""),"",IF(OR($E16="",$H16="",$H16="Proposed",$H16="Not Reported"),0,IF(AND($P16="Y",$Q16<>"Y"),0,IF(AND($K16="Point",N($L16)<=0),0,IF(AND(N($L16)<=0,N($N16)<=0,N($R16)+N($S16)<=0),0,1))))) | AA16: =IF(AND($A16="",$B16=""),"",IF($E16="","Site type missing",IF($H16="","STATUS missing",IF($H16="Proposed","STATUS = Proposed",IF($H16="Not Reported","STATUS = Not Reported",IF(AND($P16="Y",$Q16<>"Y"),"UNESCO-MAB Biosphere Reserve",IF(AND($K16="Point",N($L16)<=0),"Point without REP_AREA",IF(AND(N($L16)<=0,N($N16)<=0,N($R16)+N($S16)<=0),"No area information","")))))))) | AB16: =IF(AND($A16="",$B16=""),"",IF($K16="Point",N($L16),IF(N($N16)>0,N($N16),N($L16)))) | AC16: =IF(AND($A16="",$B16=""),"",MIN(AB16,IF(N($J16)=0,0,IF(N($J16)=2,AB16,IF(AND($K16<>"Point",N($O16)>0),N($O16),N($M16)))))) | AD16: =IF(AND($A16="",$B16=""),"",MAX(0,AB16-AC16)) | AE16: =IF(AND($A16="",$B16=""),"",IF(OR($R16<>"",$S16<>""),1,0)) | AF16: =IF(AND($A16="",$B16=""),"",IF(Z16=1,IF(AE16=1,N($R16),AD16),0)) | AG16: =IF(AND($A16="",$B16=""),"",IF(Z16=1,IF(AE16=1,N($S16),AC16),0)) | AH16: =IF(AND($A16="",$B16=""),"",IF(AND(ISNUMBER($I16),N($I16)>0),$I16,0)) | AI16: =IF(AND(NOT(AND($A16="",$B16="")),$K16="Point",N($L16)>0),SQRT(N($L16)/PI()),"") | AJ16: =IF(AND($A16="",$B16=""),"",IFERROR(VLOOKUP($G16,Lists!$D$4:$E$15,2,FALSE),"Not reported")) | AK16: =IF(AND($A16="",$B16=""),"",IF($X16<>"",$X16,IF($T16<>"Y","Not assessed",IF(AND(ISNUMBER($V16),Setup!$B$6-$V16>Setup!$B$26),"Assessment outdated",IF(NOT(ISNUMBER($W16)),"Assessed – no score",IF($W16>=Setup!$B$24,"High",IF($W16>=Setup!$B$25,"Moderate","Low"))))))) | AL16: =IF(AND($A16="",$B16=""),"",IF(Z16=0,"",IF(AND(AE16=1,N($R16)>AD16*1.01+0.001),"Net terrestrial > gross; ","")&IF(AND(AE16=1,N($S16)>AC16*1.01+0.001),"Net marine > gross; ","")&IF(AE16=0,"No net area – gross used, overlaps may be double-counted; ","")&IF(AH16=0,"STATUS_YR missing – imputed in time series; ","")&IF(AND(ISNUMBER($I16),N($I16)>Setup!$B$6),"STATUS_YR after reporting year; ","")&IF(OR($G16="",$G16="Not Reported"),"GOV_TYPE not reported; ","")&IF(AND(N($J16)=1,$K16="Point",N($M16)<=0),"Coastal point without REP_M_AREA – land/sea split unknown; ","")&IF(AND(N($J16)=0,N($S16)>0),"MARINE=0 but net marine >0; ","")&IF(AND(N($J16)=2,N($R16)>0),"MARINE=2 but net terrestrial >0; ","")&IF($K16="Point","Buffered point – coverage approximate; ","")))
A17: 101170 | B17: Tlemcen | C17: National Park | D17: National | E17: PA | F17: II | G17: Federal or national ministry or agency | H17: Designated | I17: 1993 | J17: 0 | K17: Polygon | L17: 82.25 | M17: 0 | N17: 82.011 | O17: 0 | P17: N | R17: 82.203 | S17: 0 | T17: N | Z17: =IF(AND($A17="",$B17=""),"",IF(OR($E17="",$H17="",$H17="Proposed",$H17="Not Reported"),0,IF(AND($P17="Y",$Q17<>"Y"),0,IF(AND($K17="Point",N($L17)<=0),0,IF(AND(N($L17)<=0,N($N17)<=0,N($R17)+N($S17)<=0),0,1))))) | AA17: =IF(AND($A17="",$B17=""),"",IF($E17="","Site type missing",IF($H17="","STATUS missing",IF($H17="Proposed","STATUS = Proposed",IF($H17="Not Reported","STATUS = Not Reported",IF(AND($P17="Y",$Q17<>"Y"),"UNESCO-MAB Biosphere Reserve",IF(AND($K17="Point",N($L17)<=0),"Point without REP_AREA",IF(AND(N($L17)<=0,N($N17)<=0,N($R17)+N($S17)<=0),"No area information","")))))))) | AB17: =IF(AND($A17="",$B17=""),"",IF($K17="Point",N($L17),IF(N($N17)>0,N($N17),N($L17)))) | AC17: =IF(AND($A17="",$B17=""),"",MIN(AB17,IF(N($J17)=0,0,IF(N($J17)=2,AB17,IF(AND($K17<>"Point",N($O17)>0),N($O17),N($M17)))))) | AD17: =IF(AND($A17="",$B17=""),"",MAX(0,AB17-AC17)) | AE17: =IF(AND($A17="",$B17=""),"",IF(OR($R17<>"",$S17<>""),1,0)) | AF17: =IF(AND($A17="",$B17=""),"",IF(Z17=1,IF(AE17=1,N($R17),AD17),0)) | AG17: =IF(AND($A17="",$B17=""),"",IF(Z17=1,IF(AE17=1,N($S17),AC17),0)) | AH17: =IF(AND($A17="",$B17=""),"",IF(AND(ISNUMBER($I17),N($I17)>0),$I17,0)) | AI17: =IF(AND(NOT(AND($A17="",$B17="")),$K17="Point",N($L17)>0),SQRT(N($L17)/PI()),"") | AJ17: =IF(AND($A17="",$B17=""),"",IFERROR(VLOOKUP($G17,Lists!$D$4:$E$15,2,FALSE),"Not reported")) | AK17: =IF(AND($A17="",$B17=""),"",IF($X17<>"",$X17,IF($T17<>"Y","Not assessed",IF(AND(ISNUMBER($V17),Setup!$B$6-$V17>Setup!$B$26),"Assessment outdated",IF(NOT(ISNUMBER($W17)),"Assessed – no score",IF($W17>=Setup!$B$24,"High",IF($W17>=Setup!$B$25,"Moderate","Low"))))))) | AL17: =IF(AND($A17="",$B17=""),"",IF(Z17=0,"",IF(AND(AE17=1,N($R17)>AD17*1.01+0.001),"Net terrestrial > gross; ","")&IF(AND(AE17=1,N($S17)>AC17*1.01+0.001),"Net marine > gross; ","")&IF(AE17=0,"No net area – gross used, overlaps may be double-counted; ","")&IF(AH17=0,"STATUS_YR missing – imputed in time series; ","")&IF(AND(ISNUMBER($I17),N($I17)>Setup!$B$6),"STATUS_YR after reporting year; ","")&IF(OR($G17="",$G17="Not Reported"),"GOV_TYPE not reported; ","")&IF(AND(N($J17)=1,$K17="Point",N($M17)<=0),"Coastal point without REP_M_AREA – land/sea split unknown; ","")&IF(AND(N($J17)=0,N($S17)>0),"MARINE=0 but net marine >0; ","")&IF(AND(N($J17)=2,N($R17)>0),"MARINE=2 but net terrestrial >0; ","")&IF($K17="Point","Buffered point – coverage approximate; ","")))
A18: 145569 | B18: Djurdjura | C18: UNESCO-MAB Biosphere Reserve | D18: International | E18: PA | F18: Not Applicable | G18: Not Reported | H18: Designated | I18: 1997 | J18: 0 | K18: Polygon | L18: 376.9073 | M18: 0 | N18: 379.97 | O18: 0 | P18: Y | T18: N | Y18: Excluded in GIS: UNESCO-MAB Biosphere Reserve | Z18: =IF(AND($A18="",$B18=""),"",IF(OR($E18="",$H18="",$H18="Proposed",$H18="Not Reported"),0,IF(AND($P18="Y",$Q18<>"Y"),0,IF(AND($K18="Point",N($L18)<=0),0,IF(AND(N($L18)<=0,N($N18)<=0,N($R18)+N($S18)<=0),0,1))))) | AA18: =IF(AND($A18="",$B18=""),"",IF($E18="","Site type missing",IF($H18="","STATUS missing",IF($H18="Proposed","STATUS = Proposed",IF($H18="Not Reported","STATUS = Not Reported",IF(AND($P18="Y",$Q18<>"Y"),"UNESCO-MAB Biosphere Reserve",IF(AND($K18="Point",N($L18)<=0),"Point without REP_AREA",IF(AND(N($L18)<=0,N($N18)<=0,N($R18)+N($S18)<=0),"No area information","")))))))) | AB18: =IF(AND($A18="",$B18=""),"",IF($K18="Point",N($L18),IF(N($N18)>0,N($N18),N($L18)))) | AC18: =IF(AND($A18="",$B18=""),"",MIN(AB18,IF(N($J18)=0,0,IF(N($J18)=2,AB18,IF(AND($K18<>"Point",N($O18)>0),N($O18),N($M18)))))) | AD18: =IF(AND($A18="",$B18=""),"",MAX(0,AB18-AC18)) | AE18: =IF(AND($A18="",$B18=""),"",IF(OR($R18<>"",$S18<>""),1,0)) | AF18: =IF(AND($A18="",$B18=""),"",IF(Z18=1,IF(AE18=1,N($R18),AD18),0)) | AG18: =IF(AND($A18="",$B18=""),"",IF(Z18=1,IF(AE18=1,N($S18),AC18),0)) | AH18: =IF(AND($A18="",$B18=""),"",IF(AND(ISNUMBER($I18),N($I18)>0),$I18,0)) | AI18: =IF(AND(NOT(AND($A18="",$B18="")),$K18="Point",N($L18)>0),SQRT(N($L18)/PI()),"") | AJ18: =IF(AND($A18="",$B18=""),"",IFERROR(VLOOKUP($G18,Lists!$D$4:$E$15,2,FALSE),"Not reported")) | AK18: =IF(AND($A18="",$B18=""),"",IF($X18<>"",$X18,IF($T18<>"Y","Not assessed",IF(AND(ISNUMBER($V18),Setup!$B$6-$V18>Setup!$B$26),"Assessment outdated",IF(NOT(ISNUMBER($W18)),"Assessed – no score",IF($W18>=Setup!$B$24,"High",IF($W18>=Setup!$B$25,"Moderate","Low"))))))) | AL18: =IF(AND($A18="",$B18=""),"",IF(Z18=0,"",IF(AND(AE18=1,N($R18)>AD18*1.01+0.001),"Net terrestrial > gross; ","")&IF(AND(AE18=1,N($S18)>AC18*1.01+0.001),"Net marine > gross; ","")&IF(AE18=0,"No net area – gross used, overlaps may be double-counted; ","")&IF(AH18=0,"STATUS_YR missing – imputed in time series; ","")&IF(AND(ISNUMBER($I18),N($I18)>Setup!$B$6),"STATUS_YR after reporting year; ","")&IF(OR($G18="",$G18="Not Reported"),"GOV_TYPE not reported; ","")&IF(AND(N($J18)=1,$K18="Point",N($M18)<=0),"Coastal point without REP_M_AREA – land/sea split unknown; ","")&IF(AND(N($J18)=0,N($S18)>0),"MARINE=0 but net marine >0; ","")&IF(AND(N($J18)=2,N($R18)>0),"MARINE=2 but net terrestrial >0; ","")&IF($K18="Point","Buffered point – coverage approximate; ","")))
A19: 198304 | B19: Réserve Naturelle du Lac des Oiseaux | C19: Wetland of International Importance (Ramsar Site) | D19: International | E19: PA | F19: Not Reported | G19: Federal or national ministry or agency | H19: Designated | I19: 1999 | J19: 0 | K19: Polygon | L19: 1.2 | M19: 0 | N19: 0.815 | O19: 0 | P19: N | R19: 0.817 | S19: 0 | T19: N | Z19: =IF(AND($A19="",$B19=""),"",IF(OR($E19="",$H19="",$H19="Proposed",$H19="Not Reported"),0,IF(AND($P19="Y",$Q19<>"Y"),0,IF(AND($K19="Point",N($L19)<=0),0,IF(AND(N($L19)<=0,N($N19)<=0,N($R19)+N($S19)<=0),0,1))))) | AA19: =IF(AND($A19="",$B19=""),"",IF($E19="","Site type missing",IF($H19="","STATUS missing",IF($H19="Proposed","STATUS = Proposed",IF($H19="Not Reported","STATUS = Not Reported",IF(AND($P19="Y",$Q19<>"Y"),"UNESCO-MAB Biosphere Reserve",IF(AND($K19="Point",N($L19)<=0),"Point without REP_AREA",IF(AND(N($L19)<=0,N($N19)<=0,N($R19)+N($S19)<=0),"No area information","")))))))) | AB19: =IF(AND($A19="",$B19=""),"",IF($K19="Point",N($L19),IF(N($N19)>0,N($N19),N($L19)))) | AC19: =IF(AND($A19="",$B19=""),"",MIN(AB19,IF(N($J19)=0,0,IF(N($J19)=2,AB19,IF(AND($K19<>"Point",N($O19)>0),N($O19),N($M19)))))) | AD19: =IF(AND($A19="",$B19=""),"",MAX(0,AB19-AC19)) | AE19: =IF(AND($A19="",$B19=""),"",IF(OR($R19<>"",$S19<>""),1,0)) | AF19: =IF(AND($A19="",$B19=""),"",IF(Z19=1,IF(AE19=1,N($R19),AD19),0)) | AG19: =IF(AND($A19="",$B19=""),"",IF(Z19=1,IF(AE19=1,N($S19),AC19),0)) | AH19: =IF(AND($A19="",$B19=""),"",IF(AND(ISNUMBER($I19),N($I19)>0),$I19,0)) | AI19: =IF(AND(NOT(AND($A19="",$B19="")),$K19="Point",N($L19)>0),SQRT(N($L19)/PI()),"") | AJ19: =IF(AND($A19="",$B19=""),"",IFERROR(VLOOKUP($G19,Lists!$D$4:$E$15,2,FALSE),"Not reported")) | AK19: =IF(AND($A19="",$B19=""),"",IF($X19<>"",$X19,IF($T19<>"Y","Not assessed",IF(AND(ISNUMBER($V19),Setup!$B$6-$V19>Setup!$B$26),"Assessment outdated",IF(NOT(ISNUMBER($W19)),"Assessed – no score",IF($W19>=Setup!$B$24,"High",IF($W19>=Setup!$B$25,"Moderate","Low"))))))) | AL19: =IF(AND($A19="",$B19=""),"",IF(Z19=0,"",IF(AND(AE19=1,N($R19)>AD19*1.01+0.001),"Net terrestrial > gross; ","")&IF(AND(AE19=1,N($S19)>AC19*1.01+0.001),"Net marine > gross; ","")&IF(AE19=0,"No net area – gross used, overlaps may be double-counted; ","")&IF(AH19=0,"STATUS_YR missing – imputed in time series; ","")&IF(AND(ISNUMBER($I19),N($I19)>Setup!$B$6),"STATUS_YR after reporting year; ","")&IF(OR($G19="",$G19="Not Reported"),"GOV_TYPE not reported; ","")&IF(AND(N($J19)=1,$K19="Point",N($M19)<=0),"Coastal point without REP_M_AREA – land/sea split unknown; ","")&IF(AND(N($J19)=0,N($S19)>0),"MARINE=0 but net marine >0; ","")&IF(AND(N($J19)=2,N($R19)>0),"MARINE=2 but net terrestrial >0; ","")&IF($K19="Point","Buffered point – coverage approximate; ","")))
A20: 555599910 | B20: Banc Des Kabyles Marine Reserve | C20: Specially Protected Areas of Mediterranean Importance (Barcelona Convention) | D20: Regional | E20: PA | F20: Not Assigned | G20: Federal or national ministry or agency | H20: Adopted | I20: 2001 | J20: 2 | K20: Polygon | L20: 6 | M20: 4.01 | N20: 4.005 | O20: 4.005 | P20: N | R20: 0 | S20: 4.013 | T20: N | Z20: =IF(AND($A20="",$B20=""),"",IF(OR($E20="",$H20="",$H20="Proposed",$H20="Not Reported"),0,IF(AND($P20="Y",$Q20<>"Y"),0,IF(AND($K20="Point",N($L20)<=0),0,IF(AND(N($L20)<=0,N($N20)<=0,N($R20)+N($S20)<=0),0,1))))) | AA20: =IF(AND($A20="",$B20=""),"",IF($E20="","Site type missing",IF($H20="","STATUS missing",IF($H20="Proposed","STATUS = Proposed",IF($H20="Not Reported","STATUS = Not Reported",IF(AND($P20="Y",$Q20<>"Y"),"UNESCO-MAB Biosphere Reserve",IF(AND($K20="Point",N($L20)<=0),"Point without REP_AREA",IF(AND(N($L20)<=0,N($N20)<=0,N($R20)+N($S20)<=0),"No area information","")))))))) | AB20: =IF(AND($A20="",$B20=""),"",IF($K20="Point",N($L20),IF(N($N20)>0,N($N20),N($L20)))) | AC20: =IF(AND($A20="",$B20=""),"",MIN(AB20,IF(N($J20)=0,0,IF(N($J20)=2,AB20,IF(AND($K20<>"Point",N($O20)>0),N($O20),N($M20)))))) | AD20: =IF(AND($A20="",$B20=""),"",MAX(0,AB20-AC20)) | AE20: =IF(AND($A20="",$B20=""),"",IF(OR($R20<>"",$S20<>""),1,0)) | AF20: =IF(AND($A20="",$B20=""),"",IF(Z20=1,IF(AE20=1,N($R20),AD20),0)) | AG20: =IF(AND($A20="",$B20=""),"",IF(Z20=1,IF(AE20=1,N($S20),AC20),0)) | AH20: =IF(AND($A20="",$B20=""),"",IF(AND(ISNUMBER($I20),N($I20)>0),$I20,0)) | AI20: =IF(AND(NOT(AND($A20="",$B20="")),$K20="Point",N($L20)>0),SQRT(N($L20)/PI()),"") | AJ20: =IF(AND($A20="",$B20=""),"",IFERROR(VLOOKUP($G20,Lists!$D$4:$E$15,2,FALSE),"Not reported")) | AK20: =IF(AND($A20="",$B20=""),"",IF($X20<>"",$X20,IF($T20<>"Y","Not assessed",IF(AND(ISNUMBER($V20),Setup!$B$6-$V20>Setup!$B$26),"Assessment outdated",IF(NOT(ISNUMBER($W20)),"Assessed – no score",IF($W20>=Setup!$B$24,"High",IF($W20>=Setup!$B$25,"Moderate","Low"))))))) | AL20: =IF(AND($A20="",$B20=""),"",IF(Z20=0,"",IF(AND(AE20=1,N($R20)>AD20*1.01+0.001),"Net terrestrial > gross; ","")&IF(AND(AE20=1,N($S20)>AC20*1.01+0.001),"Net marine > gross; ","")&IF(AE20=0,"No net area – gross used, overlaps may be double-counted; ","")&IF(AH20=0,"STATUS_YR missing – imputed in time series; ","")&IF(AND(ISNUMBER($I20),N($I20)>Setup!$B$6),"STATUS_YR after reporting year; ","")&IF(OR($G20="",$G20="Not Reported"),"GOV_TYPE not reported; ","")&IF(AND(N($J20)=1,$K20="Point",N($M20)<=0),"Coastal point without REP_M_AREA – land/sea split unknown; ","")&IF(AND(N($J20)=0,N($S20)>0),"MARINE=0 but net marine >0; ","")&IF(AND(N($J20)=2,N($R20)>0),"MARINE=2 but net terrestrial >0; ","")&IF($K20="Point","Buffered point – coverage approximate; ","")))
A21: 900571 | B21: Vallée d'Iherir | C21: Wetland of International Importance (Ramsar Site) | D21: International | E21: PA | F21: Not Reported | G21: Federal or national ministry or agency | H21: Designated | I21: 2001 | J21: 0 | K21: Polygon | L21: 578.9186 | M21: 0 | N21: 578.92 | O21: 0 | P21: N | R21: 0 | S21: 0 | T21: N | Y21: Overlap attributed to earlier site | Z21: =IF(AND($A21="",$B21=""),"",IF(OR($E21="",$H21="",$H21="Proposed",$H21="Not Reported"),0,IF(AND($P21="Y",$Q21<>"Y"),0,IF(AND($K21="Point",N($L21)<=0),0,IF(AND(N($L21)<=0,N($N21)<=0,N($R21)+N($S21)<=0),0,1))))) | AA21: =IF(AND($A21="",$B21=""),"",IF($E21="","Site type missing",IF($H21="","STATUS missing",IF($H21="Proposed","STATUS = Proposed",IF($H21="Not Reported","STATUS = Not Reported",IF(AND($P21="Y",$Q21<>"Y"),"UNESCO-MAB Biosphere Reserve",IF(AND($K21="Point",N($L21)<=0),"Point without REP_AREA",IF(AND(N($L21)<=0,N($N21)<=0,N($R21)+N($S21)<=0),"No area information","")))))))) | AB21: =IF(AND($A21="",$B21=""),"",IF($K21="Point",N($L21),IF(N($N21)>0,N($N21),N($L21)))) | AC21: =IF(AND($A21="",$B21=""),"",MIN(AB21,IF(N($J21)=0,0,IF(N($J21)=2,AB21,IF(AND($K21<>"Point",N($O21)>0),N($O21),N($M21)))))) | AD21: =IF(AND($A21="",$B21=""),"",MAX(0,AB21-AC21)) | AE21: =IF(AND($A21="",$B21=""),"",IF(OR($R21<>"",$S21<>""),1,0)) | AF21: =IF(AND($A21="",$B21=""),"",IF(Z21=1,IF(AE21=1,N($R21),AD21),0)) | AG21: =IF(AND($A21="",$B21=""),"",IF(Z21=1,IF(AE21=1,N($S21),AC21),0)) | AH21: =IF(AND($A21="",$B21=""),"",IF(AND(ISNUMBER($I21),N($I21)>0),$I21,0)) | AI21: =IF(AND(NOT(AND($A21="",$B21="")),$K21="Point",N($L21)>0),SQRT(N($L21)/PI()),"") | AJ21: =IF(AND($A21="",$B21=""),"",IFERROR(VLOOKUP($G21,Lists!$D$4:$E$15,2,FALSE),"Not reported")) | AK21: =IF(AND($A21="",$B21=""),"",IF($X21<>"",$X21,IF($T21<>"Y","Not assessed",IF(AND(ISNUMBER($V21),Setup!$B$6-$V21>Setup!$B$26),"Assessment outdated",IF(NOT(ISNUMBER($W21)),"Assessed – no score",IF($W21>=Setup!$B$24,"High",IF($W21>=Setup!$B$25,"Moderate","Low"))))))) | AL21: =IF(AND($A21="",$B21=""),"",IF(Z21=0,"",IF(AND(AE21=1,N($R21)>AD21*1.01+0.001),"Net terrestrial > gross; ","")&IF(AND(AE21=1,N($S21)>AC21*1.01+0.001),"Net marine > gross; ","")&IF(AE21=0,"No net area – gross used, overlaps may be double-counted; ","")&IF(AH21=0,"STATUS_YR missing – imputed in time series; ","")&IF(AND(ISNUMBER($I21),N($I21)>Setup!$B$6),"STATUS_YR after reporting year; ","")&IF(OR($G21="",$G21="Not Reported"),"GOV_TYPE not reported; ","")&IF(AND(N($J21)=1,$K21="Point",N($M21)<=0),"Coastal point without REP_M_AREA – land/sea split unknown; ","")&IF(AND(N($J21)=0,N($S21)>0),"MARINE=0 but net marine >0; ","")&IF(AND(N($J21)=2,N($R21)>0),"MARINE=2 but net terrestrial >0; ","")&IF($K21="Point","Buffered point – coverage approximate; ","")))
